Workbook

Sheet Car_sales
A1: Manufacturer | B1: Model | C1: Sales_in_thousands | D1: __year_resale_value | E1: Vehicle_type | F1: Price_in_thousands | G1: Engine_size | H1: Horsepower | I1: Wheelbase | J1: Width | K1: Length | L1: Curb_weight | M1: Fuel_capacity | N1: Fuel_efficiency | O1: Latest_Launch | P1: Power_perf_factor
A2: Acura | B2: Integra | C2: 16.919 | D2: 16.36 | E2: Passenger | F2: 21.5 | G2: 1.8 | H2: 140 | I2: 101.2 | J2: 67.3 | K2: 172.4 | L2: 2.639 | M2: 13.2 | N2: 28 | O2: 40941 | P2: 58.28015
A3: Acura | B3: TL | C3: 39.384 | D3: 19.875 | E3: Passenger | F3: 28.4 | G3: 3.2 | H3: 225 | I3: 108.1 | J3: 70.3 | K3: 192.9 | L3: 3.517 | M3: 17.2 | N3: 25 | O3: 40697 | P3: 91.370778
A4: Acura | B4: CL | C4: 14.114 | D4: 18.225 | E4: Passenger | G4: 3.2 | H4: 225 | I4: 106.9 | J4: 70.6 | K4: 192 | L4: 3.47 | M4: 17.2 | N4: 26 | O4: 40912
A5: Acura | B5: RL | C5: 8.588 | D5: 29.725 | E5: Passenger | F5: 42 | G5: 3.5 | H5: 210 | I5: 114.6 | J5: 71.4 | K5: 196.6 | L5: 3.85 | M5: 18 | N5: 22 | O5: 40612 | P5: 91.389779
A6: Audi | B6: A4 | C6: 20.397 | D6: 22.255 | E6: Passenger | F6: 23.99 | G6: 1.8 | H6: 150 | I6: 102.6 | J6: 68.2 | K6: 178 | L6: 2.998 | M6: 16.4 | N6: 27 | O6: 40824 | P6: 62.777639
A7: Audi | B7: A6 | C7: 18.78 | D7: 23.555 | E7: Passenger | F7: 33.95 | G7: 2.8 | H7: 200 | I7: 108.7 | J7: 76.1 | K7: 192 | L7: 3.561 | M7: 18.5 | N7: 22 | O7: 40764 | P7: 84.565105
A8: Audi | B8: A8 | C8: 1.38 | D8: 39 | E8: Passenger | F8: 62 | G8: 4.2 | H8: 310 | I8: 113 | J8: 74 | K8: 198.2 | L8: 3.902 | M8: 23.7 | N8: 21 | O8: 40966 | P8: 134.65686
A9: BMW | B9: 323i | C9: 19.747 | E9: Passenger | F9: 26.99 | G9: 2.5 | H9: 170 | I9: 107.3 | J9: 68.4 | K9: 176 | L9: 3.179 | M9: 16.6 | N9: 26 | O9: 40722 | P9: 71.191207
A10: BMW | B10: 328i | C10: 9.231 | D10: 28.675 | E10: Passenger | F10: 33.4 | G10: 2.8 | H10: 193 | I10: 107.3 | J10: 68.5 | K10: 176 | L10: 3.197 | M10: 16.6 | N10: 24 | O10: 40937 | P10: 81.877069
A11: BMW | B11: 528i | C11: 17.527 | D11: 36.125 | E11: Passenger | F11: 38.9 | G11: 2.8 | H11: 193 | I11: 111.4 | J11: 70.9 | K11: 188 | L11: 3.472 | M11: 18.5 | N11: 25 | O11: 40637 | P11: 83.998724
A12: Buick | B12: Century | C12: 91.561 | D12: 12.475 | E12: Passenger | F12: 21.975 | G12: 3.1 | H12: 175 | I12: 109 | J12: 72.7 | K12: 194.6 | L12: 3.368 | M12: 17.5 | N12: 25 | O12: 40849 | P12: 71.181451
A13: Buick | B13: Regal | C13: 39.35 | D13: 13.74 | E13: Passenger | F13: 25.3 | G13: 3.8 | H13: 240 | I13: 109 | J13: 72.7 | K13: 196.2 | L13: 3.543 | M13: 17.5 | N13: 23 | O13: 40789 | P13: 95.636703
A14: Buick | B14: Park Avenue | C14: 27.851 | D14: 20.19 | E14: Passenger | F14: 31.965 | G14: 3.8 | H14: 205 | I14: 113.8 | J14: 74.7 | K14: 206.8 | L14: 3.778 | M14: 18.5 | N14: 24 | O14: 40991 | P14: 85.828408
A15: Buick | B15: LeSabre | C15: 83.257 | D15: 13.36 | E15: Passenger | F15: 27.885 | G15: 3.8 | H15: 205 | I15: 112.2 | J15: 73.5 | K15: 200 | L15: 3.591 | M15: 17.5 | N15: 25 | O15: 40747 | P15: 84.254526
A16: Cadillac | B16: DeVille | C16: 63.729 | D16: 22.525 | E16: Passenger | F16: 39.895 | G16: 4.6 | H16: 275 | I16: 115.3 | J16: 74.5 | K16: 207.2 | L16: 3.978 | M16: 18.5 | N16: 22 | O16: 40962 | P16: 113.8546
A17: Cadillac | B17: Seville | C17: 15.943 | D17: 27.1 | E17: Passenger | F17: 44.475 | G17: 4.6 | H17: 275 | I17: 112.2 | J17: 75 | K17: 201 | M17: 18.5 | N17: 22 | O17: 40662 | P17: 115.62136
A18: Cadillac | B18: Eldorado | C18: 6.536 | D18: 25.725 | E18: Passenger | F18: 39.665 | G18: 4.6 | H18: 275 | I18: 108 | J18: 75.5 | K18: 200.6 | L18: 3.843 | M18: 19 | N18: 22 | O18: 40874 | P18: 113.76587
A19: Cadillac | B19: Catera | C19: 11.185 | D19: 18.225 | E19: Passenger | F19: 31.01 | G19: 3 | H19: 200 | I19: 107.4 | J19: 70.3 | K19: 194.8 | L19: 3.77 | M19: 18 | N19: 22 | O19: 40814 | P19: 83.483094
A20: Cadillac | B20: Escalade | C20: 14.785 | E20: Car | F20: 46.225 | G20: 5.7 | H20: 255 | I20: 117.5 | J20: 77 | K20: 201.2 | L20: 5.572 | M20: 30 | N20: 15 | O20: 41016 | P20: 109.50912
A21: Chevrolet | B21: Cavalier | C21: 145.519 | D21: 9.25 | E21: Passenger | F21: 13.26 | G21: 2.2 | H21: 115 | I21: 104.1 | J21: 67.9 | K21: 180.9 | L21: 2.676 | M21: 14.3 | N21: 27 | O21: 40772 | P21: 46.363347
A22: Chevrolet | B22: Malibu | C22: 135.126 | D22: 11.225 | E22: Passenger | F22: 16.535 | G22: 3.1 | H22: 170 | I22: 107 | J22: 69.4 | K22: 190.4 | L22: 3.051 | M22: 15 | N22: 25 | O22: 40987 | P22: 67.314462
A23: Chevrolet | B23: Lumina | C23: 24.629 | D23: 10.31 | E23: Passenger | F23: 18.89 | G23: 3.1 | H23: 175 | I23: 107.5 | J23: 72.5 | K23: 200.9 | L23: 3.33 | M23: 16.6 | N23: 25 | O23: 40687 | P23: 69.991396 | R23: Column | S23: Blank Count
A24: Chevrolet | B24: Monte Carlo | C24: 42.593 | D24: 11.525 | E24: Passenger | F24: 19.39 | G24: 3.4 | H24: 180 | I24: 110.5 | J24: 72.7 | K24: 197.9 | L24: 3.34 | M24: 17 | N24: 27 | O24: 40899 | P24: 72.030917 | R24: Year_resale_value | S24: 36
A25: Chevrolet | B25: Camaro | C25: 26.402 | D25: 13.025 | E25: Passenger | F25: 24.34 | G25: 3.8 | H25: 200 | I25: 101.1 | J25: 74.1 | K25: 193.2 | L25: 3.5 | M25: 16.8 | N25: 25 | O25: 40839 | P25: 81.118543 | R25: Price_in_thousands | S25: 2
A26: Chevrolet | B26: Corvette | C26: 17.947 | D26: 36.225 | E26: Passenger | F26: 45.705 | G26: 5.7 | H26: 345 | I26: 104.5 | J26: 73.6 | K26: 179.7 | L26: 3.21 | M26: 19.1 | N26: 22 | O26: 41041 | P26: 141.14115 | R26: Engine_size | S26: 1
A27: Chevrolet | B27: Prizm | C27: 32.299 | D27: 9.125 | E27: Passenger | F27: 13.96 | G27: 1.8 | H27: 120 | I27: 97.1 | J27: 66.7 | K27: 174.3 | L27: 2.398 | M27: 13.2 | N27: 33 | O27: 40797 | P27: 48.297636 | R27: Horsepower | S27: 1
A28: Chevrolet | B28: Metro | C28: 21.855 | D28: 5.16 | E28: Passenger | F28: 9.235 | G28: 1 | H28: 55 | I28: 93.1 | J28: 62.6 | K28: 149.4 | L28: 1.895 | M28: 10.3 | N28: 45 | O28: 41012 | P28: 23.276272 | R28: Wheelbase | S28: 1
A29: Chevrolet | B29: Impala | C29: 107.995 | E29: Passenger | F29: 18.89 | G29: 3.4 | H29: 180 | I29: 110.5 | J29: 73 | K29: 200 | L29: 3.389 | M29: 17 | N29: 27 | O29: 40712 | P29: 71.838039 | R29: Width | S29: 1
A30: Chrysler | B30: Sebring Coupe | C30: 7.854 | D30: 12.36 | E30: Passenger | F30: 19.84 | G30: 2.5 | H30: 163 | I30: 103.7 | J30: 69.7 | K30: 190.9 | L30: 2.967 | M30: 15.9 | N30: 24 | O30: 40924 | P30: 65.957184 | R30: Length | S30: 1
A31: Chrysler | B31: Sebring Conv. | C31: 32.775 | D31: 14.18 | E31: Passenger | F31: 24.495 | G31: 2.5 | H31: 168 | I31: 106 | J31: 69.2 | K31: 193 | L31: 3.332 | M31: 16 | N31: 24 | O31: 40864 | P31: 69.521355 | R31: Curb_weight | S31: 2
A32: Chrysler | B32: Concorde | C32: 31.148 | D32: 13.725 | E32: Passenger | F32: 22.245 | G32: 2.7 | H32: 200 | I32: 113 | J32: 74.4 | K32: 209.1 | L32: 3.452 | M32: 17 | N32: 26 | O32: 41066 | P32: 80.023782 | R32: Fuel_capacity | S32: 1
A33: Chrysler | B33: Cirrus | C33: 32.306 | D33: 12.64 | E33: Passenger | F33: 16.48 | G33: 2 | H33: 132 | I33: 108 | J33: 71 | K33: 186 | L33: 2.911 | M33: 16 | N33: 27 | O33: 40822 | P33: 53.5662 | R33: Fuel_efficiency | S33: 3
A34: Chrysler | B34: LHS | C34: 13.462 | D34: 17.325 | E34: Passenger | F34: 28.34 | G34: 3.5 | H34: 253 | I34: 113 | J34: 74.4 | K34: 207.7 | L34: 3.564 | M34: 17 | N34: 23 | O34: 41037 | P34: 101.32928 | R34: Latest_Launch | S34: 0
A35: Chrysler | B35: Town & Country | C35: 53.48 | D35: 19.54 | E35: Car | O35: 40737 | R35: Power_perf_factor | S35: 2
A36: Chrysler | B36: 300M | C36: 30.696 | E36: Passenger | F36: 29.185 | G36: 3.5 | H36: 253 | I36: 113 | J36: 74.4 | K36: 197.8 | L36: 3.567 | M36: 17 | N36: 23 | O36: 40949 | P36: 101.65524
A37: Dodge | B37: Neon | C37: 76.034 | D37: 7.75 | E37: Passenger | F37: 12.64 | G37: 2 | H37: 132 | I37: 105 | J37: 74.4 | K37: 174.4 | L37: 2.567 | M37: 12.5 | N37: 29 | O37: 40889 | P37: 52.084899
A38: Dodge | B38: Avenger | C38: 4.734 | D38: 12.545 | E38: Passenger | F38: 19.045 | G38: 2.5 | H38: 163 | I38: 103.7 | J38: 69.1 | K38: 190.2 | L38: 2.879 | M38: 15.9 | N38: 24 | O38: 41091 | P38: 65.650508 | R38: total blank value | S38: 51
A39: Dodge | B39: Stratus | C39: 71.186 | D39: 10.185 | E39: Passenger | F39: 20.23 | G39: 2.5 | H39: 168 | I39: 108 | J39: 71 | K39: 186 | L39: 3.058 | M39: 16 | N39: 24 | O39: 40847 | P39: 67.876108
A40: Dodge | B40: Intrepid | C40: 88.028 | D40: 12.275 | E40: Passenger | F40: 22.505 | G40: 2.7 | H40: 202 | I40: 113 | J40: 74.7 | K40: 203.7 | L40: 3.489 | M40: 17 | O40: 41062 | P40: 80.83147
...

Sheet Car_sales_Cleaned
A1: Manufacturer | B1: Model | C1: Sales_in_thousands | D1: __year_resale_value | E1: Vehicle_type | F1: Price_in_thousands | G1: Engine_size | H1: Horsepower | I1: Wheelbase | J1: Width | K1: Length | L1: Curb_weight | M1: Fuel_capacity | N1: Fuel_efficiency | O1: Latest_Launch | P1: Power_perf_factor
A2: Acura | B2: Integra | C2: 16.919 | D2: 16.36 | E2: Passenger | F2: 21.5 | G2: 1.8 | H2: 140 | I2: 101.2 | J2: 67.3 | K2: 172.4 | L2: 2.639 | M2: 13.2 | N2: 28 | O2: 40941 | P2: 58.28015
A3: Acura | B3: TL | C3: 39.384 | D3: 19.875 | E3: Passenger | F3: 28.4 | G3: 3.2 | H3: 225 | I3: 108.1 | J3: 70.3 | K3: 192.9 | L3: 3.517 | M3: 17.2 | N3: 25 | O3: 40697 | P3: 91.370778
A4: Acura | B4: CL | C4: 14.114 | D4: 18.225 | E4: Passenger | F4: =22.8 -> 22.8 | G4: 3.2 | H4: 225 | I4: 106.9 | J4: 70.6 | K4: 192 | L4: 3.47 | M4: 17.2 | N4: 26 | O4: 40912 | P4: =72.03 -> 72.03
A5: Acura | B5: RL | C5: 8.588 | D5: 29.725 | E5: Passenger | F5: 42 | G5: 3.5 | H5: 210 | I5: 114.6 | J5: 71.4 | K5: 196.6 | L5: 3.85 | M5: 18 | N5: 22 | O5: 40612 | P5: 91.389779 | R5: total blank value | S5: =COUNTBLANK(A1:P158) -> 0
A6: Audi | B6: A4 | C6: 20.397 | D6: 22.255 | E6: Passenger | F6: 23.99 | G6: 1.8 | H6: 150 | I6: 102.6 | J6: 68.2 | K6: 178 | L6: 2.998 | M6: 16.4 | N6: 27 | O6: 40824 | P6: 62.777639
A7: Audi | B7: A6 | C7: 18.78 | D7: 23.555 | E7: Passenger | F7: 33.95 | G7: 2.8 | H7: 200 | I7: 108.7 | J7: 76.1 | K7: 192 | L7: 3.561 | M7: 18.5 | N7: 22 | O7: 40764 | P7: 84.565105 | R7: Column | S7: Blank Count | T7: Mean | U7: Median
A8: Audi | B8: A8 | C8: 1.38 | D8: 39 | E8: Passenger | F8: 62 | G8: 4.2 | H8: 310 | I8: 113 | J8: 74 | K8: 198.2 | L8: 3.902 | M8: 23.7 | N8: 21 | O8: 40966 | P8: 134.65686 | R8: Year_resale_value | S8: =COUNTBLANK(D1:D158) -> 0 | T8: =AVERAGE(D2:D158) -> 18.669172 | U8: =MEDIAN(D2:D158) -> 14.875
A9: BMW | B9: 323i | C9: 19.747 | D9: =Car_sales_Cleaned!D2 -> 16.36 | E9: Passenger | F9: 26.99 | G9: 2.5 | H9: 170 | I9: 107.3 | J9: 68.4 | K9: 176 | L9: 3.179 | M9: 16.6 | N9: 26 | O9: 40722 | P9: 71.191207 | R9: Price_in_thousands | S9: =COUNTBLANK(F1:F158) -> 0 | T9: =AVERAGE(F1:F158) -> 27.332274 | U9: =MEDIAN(F2:F158) -> 22.8
A10: BMW | B10: 328i | C10: 9.231 | D10: 28.675 | E10: Passenger | F10: 33.4 | G10: 2.8 | H10: 193 | I10: 107.3 | J10: 68.5 | K10: 176 | L10: 3.197 | M10: 16.6 | N10: 24 | O10: 40937 | P10: 81.877069 | R10: Engine_size | S10: =COUNTBLANK(G1:G158) -> 0 | T10: =AVERAGE(G1:G158) -> 3.0605096 | U10: =MEDIAN(G2:G158) -> 3
A11: BMW | B11: 528i | C11: 17.527 | D11: 36.125 | E11: Passenger | F11: 38.9 | G11: 2.8 | H11: 193 | I11: 111.4 | J11: 70.9 | K11: 188 | L11: 3.472 | M11: 18.5 | N11: 25 | O11: 40637 | P11: 83.998724 | R11: Horsepower | S11: =COUNTBLANK(H1:H158) -> 0 | T11: =AVERAGE(H1:H158) -> 185.8949 | U11: =MEDIAN(H2:H158) -> 177.5
A12: Buick | B12: Century | C12: 91.561 | D12: 12.475 | E12: Passenger | F12: 21.975 | G12: 3.1 | H12: 175 | I12: 109 | J12: 72.7 | K12: 194.6 | L12: 3.368 | M12: 17.5 | N12: 25 | O12: 40849 | P12: 71.181451 | R12: Wheelbase | S12: =COUNTBLANK(I1:I158) -> 0 | T12: =AVERAGE(I1:I158) -> 107.48408 | U12: =MEDIAN(I2:I158) -> 107
A13: Buick | B13: Regal | C13: 39.35 | D13: 13.74 | E13: Passenger | F13: 25.3 | G13: 3.8 | H13: 240 | I13: 109 | J13: 72.7 | K13: 196.2 | L13: 3.543 | M13: 17.5 | N13: 23 | O13: 40789 | P13: 95.636703 | R13: Width | S13: =COUNTBLANK(J1:J158) -> 0 | T13: =AVERAGE(J1:J158) -> 71.146178 | U13: =MEDIAN(J2:J158) -> 70.55
A14: Buick | B14: Park Avenue | C14: 27.851 | D14: 20.19 | E14: Passenger | F14: 31.965 | G14: 3.8 | H14: 205 | I14: 113.8 | J14: 74.7 | K14: 206.8 | L14: 3.778 | M14: 18.5 | N14: 24 | O14: 40991 | P14: 85.828408 | R14: Length | S14: =COUNTBLANK(K1:K158) -> 0 | T14: =AVERAGE(K1:K158) -> 187.34713 | U14: =MEDIAN(K2:K158) -> 187.9
A15: Buick | B15: LeSabre | C15: 83.257 | D15: 13.36 | E15: Passenger | F15: 27.885 | G15: 3.8 | H15: 205 | I15: 112.2 | J15: 73.5 | K15: 200 | L15: 3.591 | M15: 17.5 | N15: 25 | O15: 40747 | P15: 84.254526 | R15: Curb_weight | S15: =COUNTBLANK(L1:L158) -> 0 | T15: =AVERAGE(L1:L158) -> 3.3775669 | U15: =MEDIAN(L2:L158) -> 3.342
A16: Cadillac | B16: DeVille | C16: 63.729 | D16: 22.525 | E16: Passenger | F16: 39.895 | G16: 4.6 | H16: 275 | I16: 115.3 | J16: 74.5 | K16: 207.2 | L16: 3.978 | M16: 18.5 | N16: 22 | O16: 40962 | P16: 113.8546 | R16: Fuel_capacity | S16: =COUNTBLANK(M1:M158) -> 0 | T16: =AVERAGE(M1:M158) -> 17.947134 | U16: =MEDIAN(M2:M158) -> 17.2
A17: Cadillac | B17: Seville | C17: 15.943 | D17: 27.1 | E17: Passenger | F17: 44.475 | G17: 4.6 | H17: 275 | I17: 112.2 | J17: 75 | K17: 201 | L17: =3.342 -> 3.342 | M17: 18.5 | N17: 22 | O17: 40662 | P17: 115.62136 | R17: Fuel_efficiency | S17: =COUNTBLANK(N1:N158) -> 0 | T17: =AVERAGE(N1:N158) -> 23.847134 | U17: =MEDIAN(N2:N158) -> 24
A18: Cadillac | B18: Eldorado | C18: 6.536 | D18: 25.725 | E18: Passenger | F18: 39.665 | G18: 4.6 | H18: 275 | I18: 108 | J18: 75.5 | K18: 200.6 | L18: 3.843 | M18: 19 | N18: 22 | O18: 40874 | P18: 113.76587 | R18: Latest_Launch | S18: =COUNTBLANK(O2:O158) -> 0 | T18: 0 | U18: 0
A19: Cadillac | B19: Catera | C19: 11.185 | D19: 18.225 | E19: Passenger | F19: 31.01 | G19: 3 | H19: 200 | I19: 107.4 | J19: 70.3 | K19: 194.8 | L19: 3.77 | M19: 18 | N19: 22 | O19: 40814 | P19: 83.483094 | R19: Power_perf_factor | S19: =COUNTBLANK(P2:P158) -> 0 | T19: =AVERAGE(P1:P158) -> 76.979724 | U19: =MEDIAN(P2:P158) -> 72.03
A20: Cadillac | B20: Escalade | C20: 14.785 | D20: =Car_sales_Cleaned!D13 -> 13.74 | E20: Car | F20: 46.225 | G20: 5.7 | H20: 255 | I20: 117.5 | J20: 77 | K20: 201.2 | L20: 5.572 | M20: 30 | N20: 15 | O20: 41016 | P20: 109.50912
A21: Chevrolet | B21: Cavalier | C21: 145.519 | D21: 9.25 | E21: Passenger | F21: 13.26 | G21: 2.2 | H21: 115 | I21: 104.1 | J21: 67.9 | K21: 180.9 | L21: 2.676 | M21: 14.3 | N21: 27 | O21: 40772 | P21: 46.363347
A22: Chevrolet | B22: Malibu | C22: 135.126 | D22: 11.225 | E22: Passenger | F22: 16.535 | G22: 3.1 | H22: 170 | I22: 107 | J22: 69.4 | K22: 190.4 | L22: 3.051 | M22: 15 | N22: 25 | O22: 40987 | P22: 67.314462
A23: Chevrolet | B23: Lumina | C23: 24.629 | D23: 10.31 | E23: Passenger | F23: 18.89 | G23: 3.1 | H23: 175 | I23: 107.5 | J23: 72.5 | K23: 200.9 | L23: 3.33 | M23: 16.6 | N23: 25 | O23: 40687 | P23: 69.991396
A24: Chevrolet | B24: Monte Carlo | C24: 42.593 | D24: 11.525 | E24: Passenger | F24: 19.39 | G24: 3.4 | H24: 180 | I24: 110.5 | J24: 72.7 | K24: 197.9 | L24: 3.34 | M24: 17 | N24: 27 | O24: 40899 | P24: 72.030917
A25: Chevrolet | B25: Camaro | C25: 26.402 | D25: 13.025 | E25: Passenger | F25: 24.34 | G25: 3.8 | H25: 200 | I25: 101.1 | J25: 74.1 | K25: 193.2 | L25: 3.5 | M25: 16.8 | N25: 25 | O25: 40839 | P25: 81.118543
A26: Chevrolet | B26: Corvette | C26: 17.947 | D26: 36.225 | E26: Passenger | F26: 45.705 | G26: 5.7 | H26: 345 | I26: 104.5 | J26: 73.6 | K26: 179.7 | L26: 3.21 | M26: 19.1 | N26: 22 | O26: 41041 | P26: 141.14115
A27: Chevrolet | B27: Prizm | C27: 32.299 | D27: 9.125 | E27: Passenger | F27: 13.96 | G27: 1.8 | H27: 120 | I27: 97.1 | J27: 66.7 | K27: 174.3 | L27: 2.398 | M27: 13.2 | N27: 33 | O27: 40797 | P27: 48.297636
A28: Chevrolet | B28: Metro | C28: 21.855 | D28: 5.16 | E28: Passenger | F28: 9.235 | G28: 1 | H28: 55 | I28: 93.1 | J28: 62.6 | K28: 149.4 | L28: 1.895 | M28: 10.3 | N28: 45 | O28: 41012 | P28: 23.276272
A29: Chevrolet | B29: Impala | C29: 107.995 | D29: =Car_sales_Cleaned!D22 -> 11.225 | E29: Passenger | F29: 18.89 | G29: 3.4 | H29: 180 | I29: 110.5 | J29: 73 | K29: 200 | L29: 3.389 | M29: 17 | N29: 27 | O29: 40712 | P29: 71.838039
A30: Chrysler | B30: Sebring Coupe | C30: 7.854 | D30: 12.36 | E30: Passenger | F30: 19.84 | G30: 2.5 | H30: 163 | I30: 103.7 | J30: 69.7 | K30: 190.9 | L30: 2.967 | M30: 15.9 | N30: 24 | O30: 40924 | P30: 65.957184
A31: Chrysler | B31: Sebring Conv. | C31: 32.775 | D31: 14.18 | E31: Passenger | F31: 24.495 | G31: 2.5 | H31: 168 | I31: 106 | J31: 69.2 | K31: 193 | L31: 3.332 | M31: 16 | N31: 24 | O31: 40864 | P31: 69.521355
A32: Chrysler | B32: Concorde | C32: 31.148 | D32: 13.725 | E32: Passenger | F32: 22.245 | G32: 2.7 | H32: 200 | I32: 113 | J32: 74.4 | K32: 209.1 | L32: 3.452 | M32: 17 | N32: 26 | O32: 41066 | P32: 80.023782
A33: Chrysler | B33: Cirrus | C33: 32.306 | D33: 12.64 | E33: Passenger | F33: 16.48 | G33: 2 | H33: 132 | I33: 108 | J33: 71 | K33: 186 | L33: 2.911 | M33: 16 | N33: 27 | O33: 40822 | P33: 53.5662
A34: Chrysler | B34: LHS | C34: 13.462 | D34: 17.325 | E34: Passenger | F34: 28.34 | G34: 3.5 | H34: 253 | I34: 113 | J34: 74.4 | K34: 207.7 | L34: 3.564 | M34: 17 | N34: 23 | O34: 41037 | P34: 101.32928
A35: Chrysler | B35: Town & Country | C35: 53.48 | D35: 19.54 | E35: Car | F35: =22.8 -> 22.8 | G35: =3 -> 3 | H35: =177.5 -> 177.5 | I35: =107 -> 107 | J35: =70.55 -> 70.55 | K35: =187.9 -> 187.9 | L35: =3.342 -> 3.342 | M35: =17.2 -> 17.2 | N35: =24 -> 24 | O35: 40737 | P35: =72.03 -> 72.03
A36: Chrysler | B36: 300M | C36: 30.696 | D36: =Car_sales_Cleaned!D29 -> 11.225 | E36: Passenger | F36: 29.185 | G36: 3.5 | H36: 253 | I36: 113 | J36: 74.4 | K36: 197.8 | L36: 3.567 | M36: 17 | N36: 23 | O36: 40949 | P36: 101.65524
A37: Dodge | B37: Neon | C37: 76.034 | D37: 7.75 | E37: Passenger | F37: 12.64 | G37: 2 | H37: 132 | I37: 105 | J37: 74.4 | K37: 174.4 | L37: 2.567 | M37: 12.5 | N37: 29 | O37: 40889 | P37: 52.084899
A38: Dodge | B38: Avenger | C38: 4.734 | D38: 12.545 | E38: Passenger | F38: 19.045 | G38: 2.5 | H38: 163 | I38: 103.7 | J38: 69.1 | K38: 190.2 | L38: 2.879 | M38: 15.9 | N38: 24 | O38: 41091 | P38: 65.650508
A39: Dodge | B39: Stratus | C39: 71.186 | D39: 10.185 | E39: Passenger | F39: 20.23 | G39: 2.5 | H39: 168 | I39: 108 | J39: 71 | K39: 186 | L39: 3.058 | M39: 16 | N39: 24 | O39: 40847 | P39: 67.876108
A40: Dodge | B40: Intrepid | C40: 88.028 | D40: 12.275 | E40: Passenger | F40: 22.505 | G40: 2.7 | H40: 202 | I40: 113 | J40: 74.7 | K40: 203.7 | L40: 3.489 | M40: 17 | N40: =24 -> 24 | O40: 41062 | P40: 80.83147
...

Sheet Cleaning_Log
A1: Column | B1: Blank Count | C1: Mean | D1: Median
A2: Year_resale_value | B2: 36 | C2: 18.072975 | D2: 14.18
A3: Price_in_thousands | B3: 2 | C3: 27.390755 | D3: 22.799
A4: Engine_size | B4: 1 | C4: 3.0608974 | D4: 3
A5: Horsepower | B5: 1 | C5: 185.94872 | D5: 177.5
A6: Wheelbase | B6: 1 | C6: 107.48718 | D6: 107
A7: Width | B7: 1 | C7: 71.15 | D7: 70.55
A8: Length | B8: 1 | C8: 187.34359 | D8: 187.9
A9: Curb_weight | B9: 2 | C9: 3.3780258 | D9: 3.342
A10: Fuel_capacity | B10: 1 | C10: 17.951923 | D10: 17.2
A11: Fuel_efficiency | B11: 3 | C11: 23.844156 | D11: 24
A12: Latest_Launch | B12: 0 | C12: 0 | D12: 0
A13: Power_perf_factor | B13: 2 | C13: 77.043591 | D13: 72.030917
A16: total blank value | B16: 51

Sheet EDA
A2: Total Records | B2: =ROWS(CarSales[Manufacturer]) -> 157
R9: Row Labels | S9: Average of Price_in_thousands
A10: Row Labels | B10: Sum of Sales_in_thousands | D10: Row Labels | E10: Average of Price_in_thousands | G10: Row Labels | H10: Sum of Sales_in_thousands | J10: Row Labels | K10: Average of Horsepower | M10: Row Labels | N10: Average of Fuel_efficiency | R10: Acura | S10: 28.675
A11: Ford | B11: 2022.635 | D11: Car | E11: 26.234122 | G11: Passenger | H11: 5015.184 | J11: Acura | K11: 200 | M11: Saturn | N11: 30.4 | R11: Audi | S11: 39.98
A12: Dodge | B12: 910.149 | D12: Passenger | E12: 27.720414 | G12: Car | H12: 3305.514 | J12: Audi | K12: 220 | M12: Chevrolet | N12: 28.444444 | R12: BMW | S12: 33.096667
A13: Toyota | B13: 740.205 | D13: Grand Total | E13: 27.332274 | G13: Grand Total | H13: 8320.698 | J13: BMW | K13: 185.33333 | M13: Hyundai | N13: 27.666667 | R13: Buick | S13: 26.78125
A14: Honda | B14: 592.674 | J14: Buick | K14: 206.25 | M14: Volkswagen | N14: 26.166667 | R14: Cadillac | S14: 40.254
A15: Chevrolet | B15: 554.365 | J15: Cadillac | K15: 256 | M15: Plymouth | N15: 25.25 | R15: Chevrolet | S15: 20.022778
A16: Nissan | B16: 399.635 | J16: Chevrolet | K16: 171.11111 | M16: Acura | N16: 25.25 | R16: Chrysler | S16: 23.340714
A17: Pontiac | B17: 370.534 | J17: Chrysler | K17: 192.35714 | M17: Toyota | N17: 25.222222 | R17: Dodge | S17: 24.213636
A18: Jeep | B18: 293.153 | J18: Dodge | K18: 199.54545 | M18: BMW | N18: 25 | R18: Ford | S18: 21.047273
A19: Buick | B19: 242.019 | J19: Ford | K19: 170.09091 | M19: Honda | N19: 25 | R19: Honda | S19: 20.277
A20: Mercury | B20: 237.999 | J20: Honda | K20: 160.4 | M20: Infiniti | N20: 25 | R20: Hyundai | S20: 12.165667
A21: Volkswagen | B21: 209.212 | J21: Hyundai | K21: 126.66667 | M21: Pontiac | N21: 24.833333 | R21: Infiniti | S21: 29.465
A22: Chrysler | B22: 201.721 | J22: Infiniti | K22: 227 | M22: Subaru | N22: 24.5 | R22: Jaguar | S22: 42.8
A23: Mitsubishi | B23: 180.895 | J23: Jaguar | K23: 240 | M23: Volvo | N23: 24.5 | R23: Jeep | S23: 20.991667
A24: Oldsmobile | B24: 178.989 | J24: Jeep | K24: 168.33333 | M24: Chrysler | N24: 24.428571 | R24: Lexus | S24: 44.055
A25: Saturn | B25: 168.85 | J25: Lexus | K25: 245.83333 | M25: Buick | N25: 24.25 | R25: Lincoln | S25: 41.69
... A40: Porsche | B40: 12.128 | J40: Volvo | K40: 182.16667 | M40: Jeep | N40: 18.666667 | R40: Grand Total | S40: 27.332274
A41: Grand Total | B41: 8320.698 | J41: Grand Total | K41: 185.8949 | M41: Grand Total | N41: 23.847134

Sheet EDA Dashboard
B5: KPI SUMMARY
